<?xml version="1.0" encoding="UTF-8"?>
<robot name="birobot">
  <joint name="left_joint1_RevoluteJoint" type="revolute">
    <origin xyz="0. 0. -0.9116406" rpy="0. 0. 0."/>
    <parent link="base_link"/>
    <child link="left_joint1_link"/>
    <axis xyz="0. 1. 0."/>
    <limit lower="-3.6651914" upper="0.5235988" effort="0." velocity="0."/>
  </joint>
  <joint name="left_joint2_RevoluteJoint" type="revolute">
    <origin xyz="0. 0. -1.281234" rpy="0. 0. 0."/>
    <parent link="left_joint1_link"/>
    <child link="left_joint2_link"/>
    <axis xyz="0. 1. 0."/>
    <limit lower="-3.6651914" upper="0.5235988" effort="0." velocity="0."/>
  </joint>
  <joint name="right_joint1_RevoluteJoint" type="revolute">
    <origin xyz="0. -1.2 -0.9116406" rpy="0. 0. 0."/>
    <parent link="base_link"/>
    <child link="right_joint1_link"/>
    <axis xyz="0. 1. 0."/>
    <limit lower="-3.6651914" upper="0.5235988" effort="0." velocity="0."/>
  </joint>
  <joint name="right_joint2_RevoluteJoint" type="revolute">
    <origin xyz="0. 0.0000001 -1.281234 " rpy="0. 0. 0."/>
    <parent link="right_joint1_link"/>
    <child link="right_joint2_link"/>
    <axis xyz="0. 1. 0."/>
    <limit lower="-3.6651914" upper="0.5235988" effort="0." velocity="0."/>
  </joint>
  <link name="base_link">
    <visual>
      <origin xyz="0. -0.6 -0.4558203" rpy="0. 0. 0."/>
      <geometry>
        <mesh filename="meshes/body.obj" scale="0.8 0.8 1.5"/>
      </geometry>
    </visual>
    <collision>
      <origin xyz="0. -0.6 -0.4558203" rpy="0. 0. 0."/>
      <geometry>
        <mesh filename="meshes/body.obj" scale="0.8 0.8 1.5"/>
      </geometry>
    </collision>
  </link>
  <link name="left_joint1_link">
    <visual>
      <origin xyz="0. 0. -0.640617" rpy="0. 0. 0."/>
      <geometry>
        <cylinder radius="0.25" length="1.2"/>
      </geometry>
    </visual>
    <collision>
      <origin xyz="0. 0. -0.640617" rpy="0. 0. 0."/>
      <geometry>
        <cylinder radius="0.25" length="1.2"/>
      </geometry>
    </collision>
  </link>
  <link name="left_joint2_link">
    <visual>
      <origin xyz="0. -0. -0.4848881" rpy="0. 0. 0."/>
      <geometry>
        <cylinder radius="0.25" length="1.2"/>
      </geometry>
    </visual>
    <collision>
      <origin xyz="0. -0. -0.4848881" rpy="0. 0. 0."/>
      <geometry>
        <cylinder radius="0.25" length="1.2"/>
      </geometry>
    </collision>
  </link>
  <link name="right_joint1_link">
    <visual>
      <origin xyz="0. 0. -0.640617" rpy="0. 0. 0."/>
      <geometry>
        <cylinder radius="0.25" length="1.2"/>
      </geometry>
    </visual>
    <collision>
      <origin xyz="0. 0. -0.640617" rpy="0. 0. 0."/>
      <geometry>
        <cylinder radius="0.25" length="1.2"/>
      </geometry>
    </collision>
  </link>
  <link name="right_joint2_link">
    <visual>
      <origin xyz="0. -0. -0.4848881" rpy="0. 0. 0."/>
      <geometry>
        <cylinder radius="0.25" length="1.2"/>
      </geometry>
    </visual>
    <collision>
      <origin xyz="0. -0. -0.4848881" rpy="0. 0. 0."/>
      <geometry>
        <cylinder radius="0.25" length="1.2"/>
      </geometry>
    </collision>
  </link>
</robot>
