<?xml version="1.0" encoding="UTF-8"?>
<robot name="lander">

  <!-- Leg 1 -->
  <joint name="leg1_PrismaticJoint" type="prismatic">
    <origin xyz="-0.2432818 0.2807126 -1.7951556" rpy="0.0094365 -0.0100893 0.0664074"/>
    <parent link="base_link"/>
    <child link="leg1_link"/>
    <axis xyz="0. 0. 1."/>
    <limit lower="0.0" upper="0.2" effort="100.0" velocity="1.0"/>
  </joint>

  <!-- Leg 2 -->
  <joint name="leg2_PrismaticJoint" type="prismatic">
    <origin xyz="-0.2313453 1.682129 -1.3760384" rpy="0.56972 0.0418672 -0.0910576"/>
    <parent link="base_link"/>
    <child link="leg2_link"/>
    <axis xyz="0. 0. 1."/>
    <limit lower="0.0" upper="0.2" effort="100.0" velocity="1.0"/>
  </joint>

  <!-- Leg 3 -->
  <joint name="leg3_PrismaticJoint" type="prismatic">
    <origin xyz="-1.4118276 0.1897153 -1.4576046" rpy="0.0056381 0.5710402 0.0709048"/>
    <parent link="base_link"/>
    <child link="leg3_link"/>
    <axis xyz="0. 0. 1."/>
    <limit lower="0.0" upper="0.2" effort="100.0" velocity="1.0"/>
  </joint>

  <!-- Leg 4 -->
  <joint name="leg4_PrismaticJoint" type="prismatic">
    <origin xyz="-1.399891 1.5911317 -1.0384876" rpy="0.6647065 0.5208261 0.2558816"/>
    <parent link="base_link"/>
    <child link="leg4_link"/>
    <axis xyz="0. 0. 1."/>
    <limit lower="0.0" upper="0.2" effort="100.0" velocity="1.0"/>
  </joint>

  <!-- Base Link -->
  <link name="base_link">
    <inertial>
      <mass value="10.0"/>
      <origin xyz="0.0 0.0 0.0" rpy="0.0 0.0 0.0"/>
      <inertia ixx="0.5" ixy="0.0" ixz="0.0" iyy="0.5" iyz="0.0" izz="0.5"/>
    </inertial>
    <visual>
      <origin xyz="-0.60986 0.7314 -0.7389924" rpy="0.3027678 0.2804044 0.0777154"/>
      <geometry>
        <box size="1.0 1.0 1.3"/>
      </geometry>
    </visual>
    <collision>
      <origin xyz="-0.60986 0.7314 -0.7389924" rpy="0.3027678 0.2804044 0.0777154"/>
      <geometry>
        <box size="1.0 1.0 1.3"/>
      </geometry>
    </collision>
  </link>

  <!-- Leg 1 Link -->
  <link name="leg1_link">
    <inertial>
      <mass value="1.0"/>
      <origin xyz="0.0 0.0 0.0" rpy="0.0 0.0 0.0"/>
      <inertia ixx="0.1" ixy="0.0" ixz="0.0" iyy="0.1" iyz="0.0" izz="0.1"/>
    </inertial>
    <visual>
      <origin xyz="0. 0. 0." rpy="0. 0. 0."/>
      <geometry>
        <box size="0.3 0.3 0.8"/>
      </geometry>
    </visual>
    <collision>
      <origin xyz="0. 0. 0." rpy="0. 0. 0."/>
      <geometry>
        <box size="0.3 0.3 0.8"/>
      </geometry>
    </collision>
  </link>

  <!-- Leg 2 Link -->
  <link name="leg2_link">
    <inertial>
      <mass value="1.0"/>
      <origin xyz="0.0 0.0 0.0" rpy="0.0 0.0 0.0"/>
      <inertia ixx="0.1" ixy="0.0" ixz="0.0" iyy="0.1" iyz="0.0" izz="0.1"/>
    </inertial>
    <visual>
      <origin xyz="0. 0. 0." rpy="0. 0. 0."/>
      <geometry>
        <box size="0.3 0.3 0.8"/>
      </geometry>
    </visual>
    <collision>
      <origin xyz="0. 0. 0." rpy="0. 0. 0."/>
      <geometry>
        <box size="0.3 0.3 0.8"/>
      </geometry>
    </collision>
  </link>

  <!-- Leg 3 Link -->
  <link name="leg3_link">
    <inertial>
      <mass value="1.0"/>
      <origin xyz="0.0 0.0 0.0" rpy="0.0 0.0 0.0"/>
      <inertia ixx="0.1" ixy="0.0" ixz="0.0" iyy="0.1" iyz="0.0" izz="0.1"/>
    </inertial>
    <visual>
      <origin xyz="0. 0. 0." rpy="0. 0. 0."/>
      <geometry>
        <box size="0.3 0.3 0.8"/>
      </geometry>
    </visual>
    <collision>
      <origin xyz="0. 0. 0." rpy="0. 0. 0."/>
      <geometry>
        <box size="0.3 0.3 0.8"/>
      </geometry>
    </collision>
  </link>

  <!-- Leg 4 Link -->
  <link name="leg4_link">
    <inertial>
      <mass value="1.0"/>
      <origin xyz="0.0 0.0 0.0" rpy="0.0 0.0 0.0"/>
      <inertia ixx="0.1" ixy="0.0" ixz="0.0" iyy="0.1" iyz="0.0" izz="0.1"/>
    </inertial>
    <visual>
      <origin xyz="0. 0. 0." rpy="0. 0. 0."/>
      <geometry>
        <box size="0.3 0.3 0.8"/>
      </geometry>
    </visual>
    <collision>
      <origin xyz="0. 0. 0." rpy="0. 0. 0."/>
      <geometry>
        <box size="0.3 0.3 0.8"/>
      </geometry>
    </collision>
  </link>

</robot>
